<robot name="simple4wheeler" xmlns:xacro="http://www.ros.org/wiki/xacro">
  
    <link name="map">
    </link>

    <link name="link_chassis">
        <!-- pose x,y,z, roll, pitch, yaw -->
        <pose>0 0 0.1 0 0 0</pose>
        <inertial>
            <mass value="5"/>
            <origin rpy="0 0 0" xyz="0 0 0.1"/>
            <inertia ixx="0.03954" 
                     ixy="0" 
                     ixz="0" 
                     iyy="0.10620" 
                     iyz="0" 
                     izz="0.10620"/>
        </inertial>
        <collision name="collision_chassis">
            <geometry>
                <box size="0.5 0.3 0.07"/>
            </geometry>
        </collision>
        <visual>
            <geometry>
                <box size="0.5 0.3 0.07"/>
            </geometry>
        </visual>
    </link>

    <joint name="joint_map" type="fixed">
        <parent link="map"/>
        <child link="link_chassis"/>
    </joint>

    <link name="link_right_back_wheel">
        <inertial>
            <mass value="0.2"/>
            <origin rpy="0 0 0" xyz="0 0 0.1"/>
            <inertia ixx="0.00052" 
                     ixy="0" 
                     ixz="0" 
                     iyy="0.00052" 
                     iyz="0" 
                     izz="0.00100"/>
        </inertial>
        <collision name="collision_right_back_wheel">
            <geometry>
                <cylinder radius="0.1" length="0.04"/>
            </geometry>
        </collision>
    
        <visual name="visual_right_back_wheel">
            <geometry>
                <cylinder radius="0.1" length="0.04"/>
            </geometry>
        </visual>
    </link>
    <joint name="joint_right_back_wheel" type="continuous">
        <origin rpy="0 0 0" xyz="0 0 0"/>
        <parent link="link_chassis"/>
        <child link="link_right_back_wheel"/>
        <axis rpy="0 0 0" xyz="1 0 0"/>
        <limit effort="10" velocity="10"/>
        <joint_properties damping="1.0" friction="1.0"/>
    </joint>
</robot>